Workbook

Sheet Results
A1: Task 3 - Experimental results
A3: Environment and parameters
A4: Item | D4: Value
A5: Java | D5: 1.8.0_452 (OpenJDK 64-Bit Server VM)
A6: OS | D6: Linux amd64
A7: Logical CPU cores available | D7: 8
A8: Bidding iterations per thread (constant for all locks) | D8: 1000
A9: Measured runs per (lock, threads) | D9: 5 (+1 discarded warm-up)
A11: Table 1 - Total execution time
A12: Mean +- sample standard deviation over 5 runs, in milliseconds.
A13: Threads | B13: TTAS (ms) | C13: CLH (ms) | D13: MCS (ms)
A14: 2 | B14: 1.39 ± 0.77 | C14: 2.77 ± 2.11 | D14: 2.13 ± 1.65
A15: 4 | B15: 1.09 ± 0.35 | C15: 2.13 ± 1.04 | D15: 1.25 ± 0.41
A16: 8 | B16: 2.02 ± 0.27 | C16: 10.69 ± 15.18 | D16: 229.96 ± 509.71
A17: 16 | B17: 8.10 ± 4.64 | C17: 10474.26 ± 11407.16 | D17: 174.74 ± 377.08
A19: Table 1b - Time per bid (total time / total bids)
A20: Each thread does the same number of iterations, so total work grows with threads; this normalised value isolates the cost of contention.
A21: Threads | B21: TTAS (us/bid) | C21: CLH (us/bid) | D21: MCS (us/bid)
A22: 2 | B22: =AVERAGEIFS('Raw Data'!$E$2:$E$61,'Raw Data'!$A$2:$A$61,"TTAS",'Raw Data'!$B$2:$B$61,$A22)/AVERAGEIFS('Raw Data'!$F$2:$F$61,'Raw Data'!$A$2:$A$61,"TTAS",'Raw Data'!$B$2:$B$61,$A22)/1000 -> 0.6952785 | C22: =AVERAGEIFS('Raw Data'!$E$2:$E$61,'Raw Data'!$A$2:$A$61,"CLH",'Raw Data'!$B$2:$B$61,$A22)/AVERAGEIFS('Raw Data'!$F$2:$F$61,'Raw Data'!$A$2:$A$61,"CLH",'Raw Data'!$B$2:$B$61,$A22)/1000 -> 1.3846682 | D22: =AVERAGEIFS('Raw Data'!$E$2:$E$61,'Raw Data'!$A$2:$A$61,"MCS",'Raw Data'!$B$2:$B$61,$A22)/AVERAGEIFS('Raw Data'!$F$2:$F$61,'Raw Data'!$A$2:$A$61,"MCS",'Raw Data'!$B$2:$B$61,$A22)/1000 -> 1.0667918
A23: 4 | B23: =AVERAGEIFS('Raw Data'!$E$2:$E$61,'Raw Data'!$A$2:$A$61,"TTAS",'Raw Data'!$B$2:$B$61,$A23)/AVERAGEIFS('Raw Data'!$F$2:$F$61,'Raw Data'!$A$2:$A$61,"TTAS",'Raw Data'!$B$2:$B$61,$A23)/1000 -> 0.2731348 | C23: =AVERAGEIFS('Raw Data'!$E$2:$E$61,'Raw Data'!$A$2:$A$61,"CLH",'Raw Data'!$B$2:$B$61,$A23)/AVERAGEIFS('Raw Data'!$F$2:$F$61,'Raw Data'!$A$2:$A$61,"CLH",'Raw Data'!$B$2:$B$61,$A23)/1000 -> 0.5336074 | D23: =AVERAGEIFS('Raw Data'!$E$2:$E$61,'Raw Data'!$A$2:$A$61,"MCS",'Raw Data'!$B$2:$B$61,$A23)/AVERAGEIFS('Raw Data'!$F$2:$F$61,'Raw Data'!$A$2:$A$61,"MCS",'Raw Data'!$B$2:$B$61,$A23)/1000 -> 0.3120181
A24: 8 | B24: =AVERAGEIFS('Raw Data'!$E$2:$E$61,'Raw Data'!$A$2:$A$61,"TTAS",'Raw Data'!$B$2:$B$61,$A24)/AVERAGEIFS('Raw Data'!$F$2:$F$61,'Raw Data'!$A$2:$A$61,"TTAS",'Raw Data'!$B$2:$B$61,$A24)/1000 -> 0.25274195 | C24: =AVERAGEIFS('Raw Data'!$E$2:$E$61,'Raw Data'!$A$2:$A$61,"CLH",'Raw Data'!$B$2:$B$61,$A24)/AVERAGEIFS('Raw Data'!$F$2:$F$61,'Raw Data'!$A$2:$A$61,"CLH",'Raw Data'!$B$2:$B$61,$A24)/1000 -> 1.3365278 | D24: =AVERAGEIFS('Raw Data'!$E$2:$E$61,'Raw Data'!$A$2:$A$61,"MCS",'Raw Data'!$B$2:$B$61,$A24)/AVERAGEIFS('Raw Data'!$F$2:$F$61,'Raw Data'!$A$2:$A$61,"MCS",'Raw Data'!$B$2:$B$61,$A24)/1000 -> 28.74534
A25: 16 | B25: =AVERAGEIFS('Raw Data'!$E$2:$E$61,'Raw Data'!$A$2:$A$61,"TTAS",'Raw Data'!$B$2:$B$61,$A25)/AVERAGEIFS('Raw Data'!$F$2:$F$61,'Raw Data'!$A$2:$A$61,"TTAS",'Raw Data'!$B$2:$B$61,$A25)/1000 -> 0.50618385 | C25: =AVERAGEIFS('Raw Data'!$E$2:$E$61,'Raw Data'!$A$2:$A$61,"CLH",'Raw Data'!$B$2:$B$61,$A25)/AVERAGEIFS('Raw Data'!$F$2:$F$61,'Raw Data'!$A$2:$A$61,"CLH",'Raw Data'!$B$2:$B$61,$A25)/1000 -> 654.64108 | D25: =AVERAGEIFS('Raw Data'!$E$2:$E$61,'Raw Data'!$A$2:$A$61,"MCS",'Raw Data'!$B$2:$B$61,$A25)/AVERAGEIFS('Raw Data'!$F$2:$F$61,'Raw Data'!$A$2:$A$61,"MCS",'Raw Data'!$B$2:$B$61,$A25)/1000 -> 10.921497
A27: Table 2 - Workload verification (total bids and final highest bid)
A28: Every bid is exactly 1.0 above the previous highest, so with correct mutual exclusion final highest bid = total bids = threads x iterations.
A29: Threads | B29: Lock | C29: Expected bids | D29: Total bids (mean) | E29: Final highest bid (mean) | F29: Correct runs
A30: 2 | B30: TTAS | C30: =A30*MAX('Raw Data'!$D$2:$D$61) -> 2000 | D30: =AVERAGEIFS('Raw Data'!$F$2:$F$61,'Raw Data'!$A$2:$A$61,$B30,'Raw Data'!$B$2:$B$61,$A30) -> 2000 | E30: =AVERAGEIFS('Raw Data'!$G$2:$G$61,'Raw Data'!$A$2:$A$61,$B30,'Raw Data'!$B$2:$B$61,$A30) -> 2000 | F30: =SUMPRODUCT(('Raw Data'!$A$2:$A$61=B30)*('Raw Data'!$B$2:$B$61=A30)*('Raw Data'!$F$2:$F$61=A30*'Raw Data'!$D$2:$D$61)*('Raw Data'!$G$2:$G$61='Raw Data'!$F$2:$F$61))&"/"&COUNTIFS('Raw Data'!$A$2:$A$61,$B30,'Raw Data'!$B$2:$B$61,$A30) -> 5/5
A31: 2 | B31: CLH | C31: =A31*MAX('Raw Data'!$D$2:$D$61) -> 2000 | D31: =AVERAGEIFS('Raw Data'!$F$2:$F$61,'Raw Data'!$A$2:$A$61,$B31,'Raw Data'!$B$2:$B$61,$A31) -> 2000 | E31: =AVERAGEIFS('Raw Data'!$G$2:$G$61,'Raw Data'!$A$2:$A$61,$B31,'Raw Data'!$B$2:$B$61,$A31) -> 2000 | F31: =SUMPRODUCT(('Raw Data'!$A$2:$A$61=B31)*('Raw Data'!$B$2:$B$61=A31)*('Raw Data'!$F$2:$F$61=A31*'Raw Data'!$D$2:$D$61)*('Raw Data'!$G$2:$G$61='Raw Data'!$F$2:$F$61))&"/"&COUNTIFS('Raw Data'!$A$2:$A$61,$B31,'Raw Data'!$B$2:$B$61,$A31) -> 5/5
A32: 2 | B32: MCS | C32: =A32*MAX('Raw Data'!$D$2:$D$61) -> 2000 | D32: =AVERAGEIFS('Raw Data'!$F$2:$F$61,'Raw Data'!$A$2:$A$61,$B32,'Raw Data'!$B$2:$B$61,$A32) -> 2000 | E32: =AVERAGEIFS('Raw Data'!$G$2:$G$61,'Raw Data'!$A$2:$A$61,$B32,'Raw Data'!$B$2:$B$61,$A32) -> 2000 | F32: =SUMPRODUCT(('Raw Data'!$A$2:$A$61=B32)*('Raw Data'!$B$2:$B$61=A32)*('Raw Data'!$F$2:$F$61=A32*'Raw Data'!$D$2:$D$61)*('Raw Data'!$G$2:$G$61='Raw Data'!$F$2:$F$61))&"/"&COUNTIFS('Raw Data'!$A$2:$A$61,$B32,'Raw Data'!$B$2:$B$61,$A32) -> 5/5
A33: 4 | B33: TTAS | C33: =A33*MAX('Raw Data'!$D$2:$D$61) -> 4000 | D33: =AVERAGEIFS('Raw Data'!$F$2:$F$61,'Raw Data'!$A$2:$A$61,$B33,'Raw Data'!$B$2:$B$61,$A33) -> 4000 | E33: =AVERAGEIFS('Raw Data'!$G$2:$G$61,'Raw Data'!$A$2:$A$61,$B33,'Raw Data'!$B$2:$B$61,$A33) -> 4000 | F33: =SUMPRODUCT(('Raw Data'!$A$2:$A$61=B33)*('Raw Data'!$B$2:$B$61=A33)*('Raw Data'!$F$2:$F$61=A33*'Raw Data'!$D$2:$D$61)*('Raw Data'!$G$2:$G$61='Raw Data'!$F$2:$F$61))&"/"&COUNTIFS('Raw Data'!$A$2:$A$61,$B33,'Raw Data'!$B$2:$B$61,$A33) -> 5/5
A34: 4 | B34: CLH | C34: =A34*MAX('Raw Data'!$D$2:$D$61) -> 4000 | D34: =AVERAGEIFS('Raw Data'!$F$2:$F$61,'Raw Data'!$A$2:$A$61,$B34,'Raw Data'!$B$2:$B$61,$A34) -> 4000 | E34: =AVERAGEIFS('Raw Data'!$G$2:$G$61,'Raw Data'!$A$2:$A$61,$B34,'Raw Data'!$B$2:$B$61,$A34) -> 4000 | F34: =SUMPRODUCT(('Raw Data'!$A$2:$A$61=B34)*('Raw Data'!$B$2:$B$61=A34)*('Raw Data'!$F$2:$F$61=A34*'Raw Data'!$D$2:$D$61)*('Raw Data'!$G$2:$G$61='Raw Data'!$F$2:$F$61))&"/"&COUNTIFS('Raw Data'!$A$2:$A$61,$B34,'Raw Data'!$B$2:$B$61,$A34) -> 5/5
A35: 4 | B35: MCS | C35: =A35*MAX('Raw Data'!$D$2:$D$61) -> 4000 | D35: =AVERAGEIFS('Raw Data'!$F$2:$F$61,'Raw Data'!$A$2:$A$61,$B35,'Raw Data'!$B$2:$B$61,$A35) -> 4000 | E35: =AVERAGEIFS('Raw Data'!$G$2:$G$61,'Raw Data'!$A$2:$A$61,$B35,'Raw Data'!$B$2:$B$61,$A35) -> 4000 | F35: =SUMPRODUCT(('Raw Data'!$A$2:$A$61=B35)*('Raw Data'!$B$2:$B$61=A35)*('Raw Data'!$F$2:$F$61=A35*'Raw Data'!$D$2:$D$61)*('Raw Data'!$G$2:$G$61='Raw Data'!$F$2:$F$61))&"/"&COUNTIFS('Raw Data'!$A$2:$A$61,$B35,'Raw Data'!$B$2:$B$61,$A35) -> 5/5
A36: 8 | B36: TTAS | C36: =A36*MAX('Raw Data'!$D$2:$D$61) -> 8000 | D36: =AVERAGEIFS('Raw Data'!$F$2:$F$61,'Raw Data'!$A$2:$A$61,$B36,'Raw Data'!$B$2:$B$61,$A36) -> 8000 | E36: =AVERAGEIFS('Raw Data'!$G$2:$G$61,'Raw Data'!$A$2:$A$61,$B36,'Raw Data'!$B$2:$B$61,$A36) -> 8000 | F36: =SUMPRODUCT(('Raw Data'!$A$2:$A$61=B36)*('Raw Data'!$B$2:$B$61=A36)*('Raw Data'!$F$2:$F$61=A36*'Raw Data'!$D$2:$D$61)*('Raw Data'!$G$2:$G$61='Raw Data'!$F$2:$F$61))&"/"&COUNTIFS('Raw Data'!$A$2:$A$61,$B36,'Raw Data'!$B$2:$B$61,$A36) -> 5/5
A37: 8 | B37: CLH | C37: =A37*MAX('Raw Data'!$D$2:$D$61) -> 8000 | D37: =AVERAGEIFS('Raw Data'!$F$2:$F$61,'Raw Data'!$A$2:$A$61,$B37,'Raw Data'!$B$2:$B$61,$A37) -> 8000 | E37: =AVERAGEIFS('Raw Data'!$G$2:$G$61,'Raw Data'!$A$2:$A$61,$B37,'Raw Data'!$B$2:$B$61,$A37) -> 8000 | F37: =SUMPRODUCT(('Raw Data'!$A$2:$A$61=B37)*('Raw Data'!$B$2:$B$61=A37)*('Raw Data'!$F$2:$F$61=A37*'Raw Data'!$D$2:$D$61)*('Raw Data'!$G$2:$G$61='Raw Data'!$F$2:$F$61))&"/"&COUNTIFS('Raw Data'!$A$2:$A$61,$B37,'Raw Data'!$B$2:$B$61,$A37) -> 5/5
A38: 8 | B38: MCS | C38: =A38*MAX('Raw Data'!$D$2:$D$61) -> 8000 | D38: =AVERAGEIFS('Raw Data'!$F$2:$F$61,'Raw Data'!$A$2:$A$61,$B38,'Raw Data'!$B$2:$B$61,$A38) -> 8000 | E38: =AVERAGEIFS('Raw Data'!$G$2:$G$61,'Raw Data'!$A$2:$A$61,$B38,'Raw Data'!$B$2:$B$61,$A38) -> 8000 | F38: =SUMPRODUCT(('Raw Data'!$A$2:$A$61=B38)*('Raw Data'!$B$2:$B$61=A38)*('Raw Data'!$F$2:$F$61=A38*'Raw Data'!$D$2:$D$61)*('Raw Data'!$G$2:$G$61='Raw Data'!$F$2:$F$61))&"/"&COUNTIFS('Raw Data'!$A$2:$A$61,$B38,'Raw Data'!$B$2:$B$61,$A38) -> 5/5
A39: 16 | B39: TTAS | C39: =A39*MAX('Raw Data'!$D$2:$D$61) -> 16000 | D39: =AVERAGEIFS('Raw Data'!$F$2:$F$61,'Raw Data'!$A$2:$A$61,$B39,'Raw Data'!$B$2:$B$61,$A39) -> 16000 | E39: =AVERAGEIFS('Raw Data'!$G$2:$G$61,'Raw Data'!$A$2:$A$61,$B39,'Raw Data'!$B$2:$B$61,$A39) -> 16000 | F39: =SUMPRODUCT(('Raw Data'!$A$2:$A$61=B39)*('Raw Data'!$B$2:$B$61=A39)*('Raw Data'!$F$2:$F$61=A39*'Raw Data'!$D$2:$D$61)*('Raw Data'!$G$2:$G$61='Raw Data'!$F$2:$F$61))&"/"&COUNTIFS('Raw Data'!$A$2:$A$61,$B39,'Raw Data'!$B$2:$B$61,$A39) -> 5/5
A40: 16 | B40: CLH | C40: =A40*MAX('Raw Data'!$D$2:$D$61) -> 16000 | D40: =AVERAGEIFS('Raw Data'!$F$2:$F$61,'Raw Data'!$A$2:$A$61,$B40,'Raw Data'!$B$2:$B$61,$A40) -> 16000 | E40: =AVERAGEIFS('Raw Data'!$G$2:$G$61,'Raw Data'!$A$2:$A$61,$B40,'Raw Data'!$B$2:$B$61,$A40) -> 16000 | F40: =SUMPRODUCT(('Raw Data'!$A$2:$A$61=B40)*('Raw Data'!$B$2:$B$61=A40)*('Raw Data'!$F$2:$F$61=A40*'Raw Data'!$D$2:$D$61)*('Raw Data'!$G$2:$G$61='Raw Data'!$F$2:$F$61))&"/"&COUNTIFS('Raw Data'!$A$2:$A$61,$B40,'Raw Data'!$B$2:$B$61,$A40) -> 5/5
A41: 16 | B41: MCS | C41: =A41*MAX('Raw Data'!$D$2:$D$61) -> 16000 | D41: =AVERAGEIFS('Raw Data'!$F$2:$F$61,'Raw Data'!$A$2:$A$61,$B41,'Raw Data'!$B$2:$B$61,$A41) -> 16000 | E41: =AVERAGEIFS('Raw Data'!$G$2:$G$61,'Raw Data'!$A$2:$A$61,$B41,'Raw Data'!$B$2:$B$61,$A41) -> 16000 | F41: =SUMPRODUCT(('Raw Data'!$A$2:$A$61=B41)*('Raw Data'!$B$2:$B$61=A41)*('Raw Data'!$F$2:$F$61=A41*'Raw Data'!$D$2:$D$61)*('Raw Data'!$G$2:$G$61='Raw Data'!$F$2:$F$61))&"/"&COUNTIFS('Raw Data'!$A$2:$A$61,$B41,'Raw Data'!$B$2:$B$61,$A41) -> 5/5
A43: Table 3 - Bids won by each bidder (whole auction)
A44: Mean over runs. B0..B15 are the bidder ids.
A45: Threads | B45: Lock | C45: B0 | D45: B1 | E45: B2 | F45: B3 | G45: B4 | H45: B5 | I45: B6 | J45: B7 | K45: B8 | L45: B9 | M45: B10 | N45: B11 | O45: B12 | P45: B13 | Q45: B14 | R45: B15
...

Sheet Raw Data
A1: lock | B1: threads | C1: run | D1: iterations | E1: exec_ns | F1: total_bids | G1: final_highest_bid | H1: final_highest_bidder | I1: mean_wait_ns | J1: p99_wait_ns | K1: max_wait_ns | L1: finish_spread_ns | M1: jain_first_half | N1: bids_won_per_bidder | O1: bids_won_first_half_per_bidder
A2: TTAS | B2: 2 | C2: 1 | D2: 1000 | E2: 2304858 | F2: 2000 | G2: 2000 | H2: 1 | I2: 870.4 | J2: 1574 | K2: 55054 | L2: 189628 | M2: 0.9593 | N2: 1000;1000 | O2: 603;397
A3: TTAS | B3: 2 | C3: 2 | D3: 1000 | E3: 2096061 | F3: 2000 | G3: 2000 | H3: 1 | I3: 730.4 | J3: 1468 | K3: 144171 | L3: 583824 | M3: 0.9273 | N3: 1000;1000 | O3: 640;360
A4: TTAS | B4: 2 | C4: 3 | D4: 1000 | E4: 1182385 | F4: 2000 | G4: 2000 | H4: 1 | I4: 483.6 | J4: 830 | K4: 6774 | L4: 176436 | M4: 0.9889 | N4: 1000;1000 | O4: 553;447
A5: TTAS | B5: 2 | C5: 4 | D5: 1000 | E5: 803951 | F5: 2000 | G5: 2000 | H5: 1 | I5: 243.6 | J5: 765 | K5: 125454 | L5: 247599 | M5: 0.8875 | N5: 1000;1000 | O5: 678;322
A6: TTAS | B6: 2 | C6: 5 | D6: 1000 | E6: 565530 | F6: 2000 | G6: 2000 | H6: 1 | I6: 182.1 | J6: 242 | K6: 56218 | L6: 172262 | M6: 0.9154 | N6: 1000;1000 | O6: 652;348
A7: TTAS | B7: 4 | C7: 1 | D7: 1000 | E7: 1667709 | F7: 4000 | G7: 4000 | H7: 3 | I7: 841 | J7: 7733 | K7: 104807 | L7: 572257 | M7: 0.7681 | N7: 1000;1000;1000;1000 | O7: 734;812;247;207
A8: TTAS | B8: 4 | C8: 2 | D8: 1000 | E8: 1039607 | F8: 4000 | G8: 4000 | H8: 0 | I8: 537.2 | J8: 1673 | K8: 806922 | L8: 236399 | M8: 0.8884 | N8: 1000;1000;1000;1000 | O8: 205;522;657;616
A9: TTAS | B9: 4 | C9: 3 | D9: 1000 | E9: 784296 | F9: 4000 | G9: 4000 | H9: 2 | I9: 237.2 | J9: 2002 | K9: 30675 | L9: 277567 | M9: 0.6653 | N9: 1000;1000;1000;1000 | O9: 1000;461;0;539
A10: TTAS | B10: 4 | C10: 4 | D10: 1000 | E10: 868348 | F10: 4000 | G10: 4000 | H10: 2 | I10: 121.1 | J10: 466 | K10: 89602 | L10: 714493 | M10: 0.5 | N10: 1000;1000;1000;1000 | O10: 1000;1000;0;0
A11: TTAS | B11: 4 | C11: 5 | D11: 1000 | E11: 1102736 | F11: 4000 | G11: 4000 | H11: 3 | I11: 518.3 | J11: 5256 | K11: 51448 | L11: 507698 | M11: 0.6476 | N11: 1000;1000;1000;1000 | O11: 172;1000;707;121
A12: TTAS | B12: 8 | C12: 1 | D12: 1000 | E12: 1856587 | F12: 8000 | G12: 8000 | H12: 6 | I12: 292.6 | J12: 2323 | K12: 107383 | L12: 1562320 | M12: 0.5365 | N12: 1000;1000;1000;1000;1000;1000;1000;1000 | O12: 1000;1000;1000;844;121;35;0;0
A13: TTAS | B13: 8 | C13: 2 | D13: 1000 | E13: 2251984 | F13: 8000 | G13: 8000 | H13: 7 | I13: 1120.1 | J13: 10939 | K13: 313200 | L13: 1823952 | M13: 0.6541 | N13: 1000;1000;1000;1000;1000;1000;1000;1000 | O13: 1000;1000;235;800;161;145;551;108
... A61: MCS | B61: 16 | C61: 5 | D61: 1000 | E61: 6412667 | F61: 16000 | G61: 16000 | H61: 11 | I61: 1082.9 | J61: 1409 | K61: 4290505 | L61: 6029461 | M61: 0.5227 | N61: 1000;1000;1000;1000;1000;1000;1000;1000;1000;1000;1000;1000;1000;1000;1000;1000 | O61: 1000;1000;1000;1000;1000;989;914;893;204;0;0;0;0;0;0;0
